Traceback (most recent call last):
  File "/usr/share/miniconda/envs/o2/lib/python3.8/site-packages/jupyter_cache/executors/utils.py", line 51, in single_nb_execution
    executenb(
  File "/usr/share/miniconda/envs/o2/lib/python3.8/site-packages/nbclient/client.py", line 1112, in execute
    return NotebookClient(nb=nb, resources=resources, km=km, **kwargs).execute()
  File "/usr/share/miniconda/envs/o2/lib/python3.8/site-packages/nbclient/util.py", line 74, in wrapped
    return just_run(coro(*args, **kwargs))
  File "/usr/share/miniconda/envs/o2/lib/python3.8/site-packages/nbclient/util.py", line 53, in just_run
    return loop.run_until_complete(coro)
  File "/usr/share/miniconda/envs/o2/lib/python3.8/asyncio/base_events.py", line 616, in run_until_complete
    return future.result()
  File "/usr/share/miniconda/envs/o2/lib/python3.8/site-packages/nbclient/client.py", line 553, in async_execute
    await self.async_execute_cell(
  File "/usr/share/miniconda/envs/o2/lib/python3.8/site-packages/nbclient/client.py", line 857, in async_execute_cell
    self._check_raise_for_error(cell, exec_reply)
  File "/usr/share/miniconda/envs/o2/lib/python3.8/site-packages/nbclient/client.py", line 760, in _check_raise_for_error
    raise CellExecutionError.from_cell_and_msg(cell, exec_reply_content)
nbclient.exceptions.CellExecutionError: An error occurred while executing the following cell:
------------------
import plot_utils

print(plot_utils.configs)
------------------

[0;31m---------------------------------------------------------------------------[0m
[0;31mModuleNotFoundError[0m                       Traceback (most recent call last)
[0;32m<ipython-input-1-31163bc13606>[0m in [0;36m<module>[0;34m[0m
[0;32m----> 1[0;31m [0;32mimport[0m [0mplot_utils[0m[0;34m[0m[0;34m[0m[0m
[0m[1;32m      2[0m [0;34m[0m[0m
[1;32m      3[0m [0mprint[0m[0;34m([0m[0mplot_utils[0m[0;34m.[0m[0mconfigs[0m[0;34m)[0m[0;34m[0m[0;34m[0m[0m

[0;32m~/work/ligo-o2-bbh-cloud/ligo-o2-bbh-cloud/analysis/plot_utils.py[0m in [0;36m<module>[0;34m[0m
[1;32m      6[0m [0;34m[0m[0m
[1;32m      7[0m [0;32mimport[0m [0mnumpy[0m [0;32mas[0m [0mnp[0m[0;34m[0m[0;34m[0m[0m
[0;32m----> 8[0;31m [0;32mimport[0m [0mpandas[0m [0;32mas[0m [0mpd[0m[0;34m[0m[0;34m[0m[0m
[0m[1;32m      9[0m [0;34m[0m[0m
[1;32m     10[0m [0;32mfrom[0m [0mbokeh[0m[0;34m.[0m[0mio[0m [0;32mimport[0m [0moutput_notebook[0m[0;34m,[0m [0mshow[0m[0;34m[0m[0;34m[0m[0m

[0;31mModuleNotFoundError[0m: No module named 'pandas'
ModuleNotFoundError: No module named 'pandas'

